<mujoco model="Mallet">
    <worldbody>
        <body name="mallet" pos="0 0 0.05">
            <inertial pos="0 0 0" mass="0.283" diaginertia="0.005 0.005 0.005"/>
            <joint name="mallet_x" type="slide" axis="1 0 0"/>
            <joint name="mallet_y" type="slide" axis="0 1 0"/>
            <geom name="mallet_geom" type="cylinder" size="0.04815 0.03" rgba="0.3 0.3 0.3 1"/>
        </body>
    </worldbody>
    <actuator>
        <velocity joint="mallet_x"/>
        <velocity joint="mallet_y"/>
    </actuator>
</mujoco>