<mujoco model="Mallet">
    <worldbody>
        <body name="left_mallet" pos="0 0 0.05">
            <inertial pos="0 0 0" mass="0.283" diaginertia="0.005 0.005 0.005"/>
            <joint name="left_mallet_x" type="slide" axis="1 0 0"/>
            <joint name="left_mallet_y" type="slide" axis="0 1 0"/>
            <geom name="left_mallet_geom" type="cylinder" size="0.04815 0.03" rgba="0.3 0.3 0.3 1"/>
        </body>
        <body name="right_mallet" pos="0 0 0.05">
            <inertial pos="0 0 0" mass="0.283" diaginertia="0.005 0.005 0.005"/>
            <joint name="right_mallet_x" type="slide" axis="1 0 0"/>
            <joint name="right_mallet_y" type="slide" axis="0 1 0"/>
            <geom name="right_mallet_geom" type="cylinder" size="0.04815 0.03" rgba="0.3 0.3 0.3 1"/>
        </body>
    </worldbody>
    <actuator>
        <motor name="left_mallet_x_motor" joint="left_mallet_x" gear="1"/>
        <motor name="left_mallet_y_motor" joint="left_mallet_y" gear="1"/>
        <motor name="right_mallet_x_motor" joint="right_mallet_x" gear="1"/>
        <motor name="right_mallet_y_motor" joint="right_mallet_y" gear="1"/>
    </actuator>
</mujoco>